<mujoco model="go2_arm">
    <compiler angle="radian" meshdir="assets" autolimits="true" />

    <option cone="elliptic" impratio="100" />

    <default>
        <default class="go2">
            <geom friction="0.6" margin="0.001" condim="1" />
            <joint axis="0 1 0" damping="2" armature="0.01" frictionloss="0.2" />
            <motor ctrlrange="-23.7 23.7" />
            <default class="abduction">
                <joint axis="1 0 0" range="-1.0472 1.0472" />
            </default>
            <default class="hip">
                <default class="front_hip">
                    <joint range="-1.5708 3.4907" />
                </default>
                <default class="back_hip">
                    <joint range="-0.5236 4.5379" />
                </default>
            </default>
            <default class="knee">
                <joint range="-2.7227 -0.83776" />
                <motor ctrlrange="-45.43 45.43" />
            </default>
            <default class="waist">
                <joint axis="0 0 1" range="-3.14158 3.14158" damping="2.86" />
                <position ctrlrange="-3.14158 3.14158" kp="25" />
            </default>
            <default class="shoulder">
                <joint range="-1.85005 1.25664" armature="0.004" frictionloss="0.06" damping="6.25" />
                <position ctrlrange="-1.85005 1.25664" kp="76" forcerange="-57 57" />
            </default>
            <default class="elbow">
                <joint range="-1.76278 1.6057" armature="0.072" frictionloss="1.74" damping="8.15" />
                <position ctrlrange="-1.76278 1.6057" kp="106" forcerange="-25 25" />
            </default>
            <default class="forearm_roll">
                <joint axis="1 0 0" range="-3.14158 3.14158" armature="0.060" damping="3.07" />
                <position ctrlrange="-3.14158 3.14158" kp="35" forcerange="-10 10" />
            </default>
            <default class="wrist_angle">
                <joint range="-1.8675 2.23402" damping="1.18" />
                <position ctrlrange="-1.8675 2.23402" kp="8" />
            </default>
            <default class="wrist_rotate">
                <joint axis="1 0 0" range="-3.14158 3.14158" damping="0.78" />
                <position ctrlrange="-3.14158 3.14158" kp="7" />
            </default>
            <default class="finger">
                <joint type="slide" armature="0.251" damping="10" />
                <position ctrlrange="0.021 0.057" kp="300" />
                <default class="left_finger">
                    <joint range="0.021 0.057" />
                </default>
                <default class="right_finger">
                    <joint range="-0.057 -0.021" />
                </default>
            </default>
            <default class="visual">
                <geom type="mesh" contype="0" conaffinity="0" group="2" />
            </default>
            <default class="collision">
                <geom group="3" />
                <default class="foot">
                    <geom size="0.022" pos="-0.002 0 -0.213" priority="1" solimp="0.015 1 0.022"
                        condim="6"
                        friction="0.8 0.02 0.01" />
                </default>
                <default class="finger_collision">
                    <geom condim="4" solimp="2 1 0.01" solref="0.01 1" friction="1 0.005 0.0001" />
                </default>
            </default>
        </default>
    </default>

    <asset>
        <material name="metal" rgba=".9 .95 .95 1" />
        <material name="black" rgba="0 0 0 1" />
        <material name="white" rgba="1 1 1 1" />
        <material name="gray" rgba="0.671705 0.692426 0.774270 1" />

        <mesh file="base_0.obj" />
        <mesh file="base_1.obj" />
        <mesh file="base_2.obj" />
        <mesh file="base_3.obj" />
        <mesh file="base_4.obj" />
        <mesh file="hip_0.obj" />
        <mesh file="hip_1.obj" />
        <mesh file="thigh_0.obj" />
        <mesh file="thigh_1.obj" />
        <mesh file="thigh_mirror_0.obj" />
        <mesh file="thigh_mirror_1.obj" />
        <mesh file="calf_0.obj" />
        <mesh file="calf_1.obj" />
        <mesh file="calf_mirror_0.obj" />
        <mesh file="calf_mirror_1.obj" />
        <mesh file="foot.obj" />

        <mesh file="vx300s_1_base.stl" scale="0.001 0.001 0.001" />
        <mesh file="vx300s_2_shoulder.stl" scale="0.001 0.001 0.001" />
        <mesh file="vx300s_3_upper_arm.stl" scale="0.001 0.001 0.001" />
        <mesh file="vx300s_4_upper_forearm.stl" scale="0.001 0.001 0.001" />
        <mesh file="vx300s_5_lower_forearm.stl" scale="0.001 0.001 0.001" />
        <mesh file="vx300s_6_wrist.stl" scale="0.001 0.001 0.001" />
        <mesh file="vx300s_7_gripper.stl" scale="0.001 0.001 0.001" />
        <mesh file="vx300s_8_gripper_prop.stl" scale="0.001 0.001 0.001" />
        <mesh file="vx300s_9_gripper_bar.stl" scale="0.001 0.001 0.001" />
        <mesh file="vx300s_10_gripper_finger.stl" scale="0.001 0.001 0.001" />
    </asset>

    <worldbody>
        <body name="trunk" pos="0 0 0.445" childclass="go2">
            <inertial pos="0.021112 0 -0.005366" quat="-0.000543471 0.713435 -0.00173769 0.700719"
                mass="6.921"
                diaginertia="0.107027 0.0980771 0.0244531" />
            <freejoint />
            <geom mesh="base_0" material="black" class="visual" />
            <geom mesh="base_1" material="black" class="visual" />
            <geom mesh="base_2" material="black" class="visual" />
            <geom mesh="base_3" material="white" class="visual" />
            <geom mesh="base_4" material="gray" class="visual" />
            <geom size="0.1881 0.04675 0.057" type="box" class="collision" />
            <geom size="0.05 0.045" pos="0.285 0 0.01" type="cylinder" class="collision" />
            <geom size="0.047" pos="0.293 0 -0.06" class="collision" />
            <site name="imu" pos="-0.02557 0 0.04232" />

            <site name="torso" />
            <site name="head" class="task" pos="0.3 0 0.0" />

            <body name="FL_hip" pos="0.1934 0.0465 0">
                <inertial pos="-0.0054 0.00194 -0.000105" quat="0.497014 0.499245 0.505462 0.498237"
                    mass="0.678"
                    diaginertia="0.00088403 0.000596003 0.000479967" />
                <joint name="FL_hip_joint" class="abduction" />
                <geom mesh="hip_0" material="metal" class="visual" />
                <geom mesh="hip_1" material="gray" class="visual" />
                <geom size="0.046 0.02" pos="0 0.08 0" quat="1 1 0 0" type="cylinder"
                    class="collision" />
                <body name="FL_thigh" pos="0 0.0955 0">
                    <inertial pos="-0.00374 -0.0223 -0.0327"
                        quat="0.829533 0.0847635 -0.0200632 0.551623" mass="1.152"
                        diaginertia="0.00594973 0.00584149 0.000878787" />
                    <joint name="FL_thigh_joint" class="front_hip" />
                    <geom mesh="thigh_0" material="metal" class="visual" />
                    <geom mesh="thigh_1" material="gray" class="visual" />
                    <geom size="0.1065 0.01225 0.017" pos="0 0 -0.1065" quat="0.707107 0 0.707107 0"
                        type="box" class="collision" />
                    <body name="FL_calf" pos="0 0 -0.213">
                        <inertial pos="0.00629595 -0.000622121 -0.141417"
                            quat="0.710672 0.00154099 -0.00450087 0.703508"
                            mass="0.241352" diaginertia="0.0014901 0.00146356 5.31397e-05" />
                        <joint name="FL_calf_joint" class="knee" />
                        <geom mesh="calf_0" material="gray" class="visual" />
                        <geom mesh="calf_1" material="black" class="visual" />
                        <geom size="0.012 0.06" pos="0.008 0 -0.06" quat="0.994493 0 -0.104807 0"
                            type="cylinder" class="collision" />
                        <geom size="0.011 0.0325" pos="0.02 0 -0.148" quat="0.999688 0 0.0249974 0"
                            type="cylinder" class="collision" />
                        <geom pos="0 0 -0.213" mesh="foot" class="visual" material="black" />
                        <geom name="FL" class="foot" />
                        <site name="FL" pos="0 0 -0.213" type="sphere" size=".015" />
                    </body>
                </body>
            </body>
            <body name="FR_hip" pos="0.1934 -0.0465 0">
                <inertial pos="-0.0054 -0.00194 -0.000105"
                    quat="0.498237 0.505462 0.499245 0.497014" mass="0.678"
                    diaginertia="0.00088403 0.000596003 0.000479967" />
                <joint name="FR_hip_joint" class="abduction" />
                <geom mesh="hip_0" material="metal" class="visual" quat="4.63268e-05 1 0 0" />
                <geom mesh="hip_1" material="gray" class="visual" quat="4.63268e-05 1 0 0" />
                <geom size="0.046 0.02" pos="0 -0.08 0" quat="0.707107 0.707107 0 0" type="cylinder"
                    class="collision" />
                <body name="FR_thigh" pos="0 -0.0955 0">
                    <inertial pos="-0.00374 0.0223 -0.0327"
                        quat="0.551623 -0.0200632 0.0847635 0.829533" mass="1.152"
                        diaginertia="0.00594973 0.00584149 0.000878787" />
                    <joint name="FR_thigh_joint" class="front_hip" />
                    <geom mesh="thigh_mirror_0" material="metal" class="visual" />
                    <geom mesh="thigh_mirror_1" material="gray" class="visual" />
                    <geom size="0.1065 0.01225 0.017" pos="0 0 -0.1065" quat="0.707107 0 0.707107 0"
                        type="box" class="collision" />
                    <body name="FR_calf" pos="0 0 -0.213">
                        <inertial pos="0.00629595 0.000622121 -0.141417"
                            quat="0.703508 -0.00450087 0.00154099 0.710672"
                            mass="0.241352" diaginertia="0.0014901 0.00146356 5.31397e-05" />
                        <joint name="FR_calf_joint" class="knee" />
                        <geom mesh="calf_mirror_0" material="gray" class="visual" />
                        <geom mesh="calf_mirror_1" material="black" class="visual" />
                        <geom size="0.013 0.06" pos="0.01 0 -0.06" quat="0.995004 0 -0.0998334 0"
                            type="cylinder" class="collision" />
                        <geom size="0.011 0.0325" pos="0.02 0 -0.148" quat="0.999688 0 0.0249974 0"
                            type="cylinder" class="collision" />
                        <geom pos="0 0 -0.213" mesh="foot" class="visual" material="black" />
                        <geom name="FR" class="foot" />
                        <site name="FR" pos="0 0 -0.213" type="sphere" size=".015" />
                    </body>
                </body>
            </body>
            <body name="HL_hip" pos="-0.1934 0.0465 0">
                <inertial pos="0.0054 0.00194 -0.000105" quat="0.505462 0.498237 0.497014 0.499245"
                    mass="0.678"
                    diaginertia="0.00088403 0.000596003 0.000479967" />
                <joint name="RL_hip_joint" class="abduction" />
                <geom mesh="hip_0" material="metal" class="visual" quat="4.63268e-05 0 1 0" />
                <geom mesh="hip_1" material="gray" class="visual" quat="4.63268e-05 0 1 0" />
                <geom size="0.046 0.02" pos="0 0.08 0" quat="0.707107 0.707107 0 0" type="cylinder"
                    class="collision" />
                <body name="RL_thigh" pos="0 0.0955 0">
                    <inertial pos="-0.00374 -0.0223 -0.0327"
                        quat="0.829533 0.0847635 -0.0200632 0.551623" mass="1.152"
                        diaginertia="0.00594973 0.00584149 0.000878787" />
                    <joint name="RL_thigh_joint" class="back_hip" />
                    <geom mesh="thigh_0" material="metal" class="visual" />
                    <geom mesh="thigh_1" material="gray" class="visual" />
                    <geom size="0.1065 0.01225 0.017" pos="0 0 -0.1065" quat="0.707107 0 0.707107 0"
                        type="box" class="collision" />
                    <body name="RL_calf" pos="0 0 -0.213">
                        <inertial pos="0.00629595 -0.000622121 -0.141417"
                            quat="0.710672 0.00154099 -0.00450087 0.703508"
                            mass="0.241352" diaginertia="0.0014901 0.00146356 5.31397e-05" />
                        <joint name="RL_calf_joint" class="knee" />
                        <geom mesh="calf_0" material="gray" class="visual" />
                        <geom mesh="calf_1" material="black" class="visual" />
                        <geom size="0.013 0.06" pos="0.01 0 -0.06" quat="0.995004 0 -0.0998334 0"
                            type="cylinder" class="collision" />
                        <geom size="0.011 0.0325" pos="0.02 0 -0.148" quat="0.999688 0 0.0249974 0"
                            type="cylinder" class="collision" />
                        <geom pos="0 0 -0.213" mesh="foot" class="visual" material="black" />
                        <geom name="HL" class="foot" />
                        <site name="RL" pos="0 0 -0.213" type="sphere" size=".015" />
                    </body>
                </body>
            </body>
            <body name="HR_hip" pos="-0.1934 -0.0465 0">
                <inertial pos="0.0054 -0.00194 -0.000105" quat="0.499245 0.497014 0.498237 0.505462"
                    mass="0.678"
                    diaginertia="0.00088403 0.000596003 0.000479967" />
                <joint name="RR_hip_joint" class="abduction" />
                <geom mesh="hip_0" material="metal" class="visual"
                    quat="2.14617e-09 4.63268e-05 4.63268e-05 -1" />
                <geom mesh="hip_1" material="gray" class="visual"
                    quat="2.14617e-09 4.63268e-05 4.63268e-05 -1" />
                <geom size="0.046 0.02" pos="0 -0.08 0" quat="0.707107 0.707107 0 0" type="cylinder"
                    class="collision" />
                <body name="RR_thigh" pos="0 -0.0955 0">
                    <inertial pos="-0.00374 0.0223 -0.0327"
                        quat="0.551623 -0.0200632 0.0847635 0.829533" mass="1.152"
                        diaginertia="0.00594973 0.00584149 0.000878787" />
                    <joint name="RR_thigh_joint" class="back_hip" />
                    <geom mesh="thigh_mirror_0" material="metal" class="visual" />
                    <geom mesh="thigh_mirror_1" material="gray" class="visual" />
                    <geom size="0.1065 0.01225 0.017" pos="0 0 -0.1065" quat="0.707107 0 0.707107 0"
                        type="box" class="collision" />
                    <body name="RR_calf" pos="0 0 -0.213">
                        <inertial pos="0.00629595 0.000622121 -0.141417"
                            quat="0.703508 -0.00450087 0.00154099 0.710672"
                            mass="0.241352" diaginertia="0.0014901 0.00146356 5.31397e-05" />
                        <joint name="RR_calf_joint" class="knee" />
                        <geom mesh="calf_mirror_0" material="gray" class="visual" />
                        <geom mesh="calf_mirror_1" material="black" class="visual" />
                        <geom size="0.013 0.06" pos="0.01 0 -0.06" quat="0.995004 0 -0.0998334 0"
                            type="cylinder" class="collision" />
                        <geom size="0.011 0.0325" pos="0.02 0 -0.148" quat="0.999688 0 0.0249974 0"
                            type="cylinder" class="collision" />
                        <geom pos="0 0 -0.213" mesh="foot" class="visual" material="black" />
                        <geom name="HR" class="foot" />
                        <site name="RR" pos="0 0 -0.213" type="sphere" size=".015" />
                    </body>
                </body>
            </body>

            <body name="shoulder_link" pos="0 0 0.079">
                <inertial pos="0.000259233 -3.3552e-06 0.0116129"
                    quat="-0.476119 0.476083 0.52279 0.522826" mass="0.798614"
                    diaginertia="0.00120156 0.00113744 0.0009388" />
                <joint name="waist" class="waist" />
                <geom pos="0 0 -0.003" quat="1 0 0 1" class="visual" mesh="vx300s_2_shoulder" />
                <geom pos="0 0 -0.003" quat="1 0 0 1" mesh="vx300s_2_shoulder" class="collision" />
                <body name="upper_arm_link" pos="0 0 0.04805">
                    <inertial pos="0.0206949 4e-10 0.226459" quat="0 0.0728458 0 0.997343"
                        mass="0.792592"
                        diaginertia="0.00911338 0.008925 0.000759317" />
                    <joint name="shoulder" class="shoulder" />
                    <geom quat="1 0 0 1" class="visual" mesh="vx300s_3_upper_arm" />
                    <geom quat="1 0 0 1" class="collision" mesh="vx300s_3_upper_arm" />
                    <body name="upper_forearm_link" pos="0.05955 0 0.3">
                        <inertial pos="0.105723 0 0" quat="-0.000621631 0.704724 0.0105292 0.709403"
                            mass="0.322228"
                            diaginertia="0.00144107 0.00134228 0.000152047" />
                        <joint name="elbow" class="elbow" />
                        <geom class="visual" mesh="vx300s_4_upper_forearm" />
                        <geom class="collision" mesh="vx300s_4_upper_forearm" />
                        <body name="lower_forearm_link" pos="0.2 0 0">
                            <inertial pos="0.0513477 0.00680462 0"
                                quat="-0.702604 -0.0796724 -0.702604 0.0796724" mass="0.414823"
                                diaginertia="0.0005911 0.000546493 0.000155707" />
                            <joint name="forearm_roll" class="forearm_roll" />
                            <geom quat="0 1 0 0" class="visual" mesh="vx300s_5_lower_forearm" />
                            <geom quat="0 1 0 0" class="collision" mesh="vx300s_5_lower_forearm" />
                            <body name="wrist_link" pos="0.1 0 0">
                                <inertial pos="0.046743 -7.6652e-06 0.010565"
                                    quat="-0.00100191 0.544586 0.0026583 0.8387"
                                    mass="0.115395"
                                    diaginertia="5.45707e-05 4.63101e-05 4.32692e-05" />
                                <joint name="wrist_angle" class="wrist_angle" />
                                <geom quat="1 0 0 1" class="visual" mesh="vx300s_6_wrist" />
                                <geom quat="1 0 0 1" class="collision" mesh="vx300s_6_wrist" />
                                <body name="gripper_link" pos="0.069744 0 0">
                                    <inertial pos="0.0395662 -2.56311e-07 0.00400649"
                                        quat="0.62033 0.619916 -0.339682 0.339869"
                                        mass="0.251652"
                                        diaginertia="0.000689546 0.000650316 0.000468142" />
                                    <joint name="wrist_rotate" class="wrist_rotate" />
                                    <geom pos="-0.02 0 0" quat="1 0 0 1" class="visual"
                                        mesh="vx300s_7_gripper" />
                                    <geom pos="-0.02 0 0" quat="1 0 0 1" class="collision"
                                        mesh="vx300s_7_gripper" />
                                    <geom pos="-0.020175 0 0" quat="1 0 0 1" class="visual"
                                        mesh="vx300s_9_gripper_bar" />
                                    <geom pos="-0.020175 0 0" quat="1 0 0 1" class="collision"
                                        mesh="vx300s_9_gripper_bar" />
                                    <site name="pinch" pos="0.1 0 0" size="0.005"
                                        rgba="0.6 0.3 0.3 1" group="5" />
                                    <site name="eff" size="0.01" pos="0 0.0 0.0" quat="1 0 0 0"
                                        rgba="1 0 0 1" group="1" />
                                    <body name="gripper_prop_link" pos="0.0485 0 0">
                                        <inertial pos="0.002378 2.85e-08 0"
                                            quat="0 0 0.897698 0.440611" mass="0.008009"
                                            diaginertia="4.2979e-06 2.8868e-06 1.5314e-06" />
                                        <geom pos="-0.0685 0 0" quat="1 0 0 1" class="visual"
                                            mesh="vx300s_8_gripper_prop" />
                                        <geom pos="-0.0685 0 0" quat="1 0 0 1" class="collision"
                                            mesh="vx300s_8_gripper_prop" />
                                    </body>
                                    <body name="left_finger_link" pos="0.0687 0 0">
                                        <inertial pos="0.017344 -0.0060692 0"
                                            quat="0.449364 0.449364 -0.54596 -0.54596"
                                            mass="0.034796"
                                            diaginertia="2.48003e-05 1.417e-05 1.20797e-05" />
                                        <joint name="left_finger" class="left_finger" />
                                        <geom pos="-0.0404 -0.0575 0" quat="-1 1 -1 1"
                                            class="visual" mesh="vx300s_10_gripper_finger" />
                                        <geom class="finger_collision" type="box"
                                            name="left_finger_pad_0" size="0.01405 0.01405 0.001"
                                            pos="0.0478 -0.0125 0.0106" quat="0.65 0.65 -0.27 0.27" />
                                        <geom class="finger_collision" type="box"
                                            name="left_finger_pad_1" size="0.01405 0.01405 0.001"
                                            pos="0.0478 -0.0125 -0.0106" quat="0.65 0.65 -0.27 0.27" />
                                        <geom class="finger_collision" type="box"
                                            name="left_finger_pad_2" size="0.01058 0.01058 0.001"
                                            pos="0.0571 -0.0125 0.0" quat="1 1 0 0" />
                                        <geom class="finger_collision" type="box"
                                            name="left_finger_pad_3" size="0.01 0.0105 0.001"
                                            pos="0.0378 -0.0125 0.0" quat="1 1 0 0" />
                                        <geom class="finger_collision" type="box"
                                            name="left_finger_pad_4" size="0.015 0.0105 0.001"
                                            pos="0.0128 -0.0125 0.0" quat="1 1 0 0" />
                                        <geom class="finger_collision" type="box"
                                            name="left_finger_pad_5" size="0.01 0.0105 0.001"
                                            pos="0.0378 -0.0125 0.02" quat="1 1 0 0" />
                                        <geom class="finger_collision" type="box"
                                            name="left_finger_pad_6" size="0.015 0.0105 0.001"
                                            pos="0.0128 -0.0125 0.02" quat="1 1 0 0" />
                                        <geom class="finger_collision" type="box"
                                            name="left_finger_pad_7" size="0.01 0.0105 0.001"
                                            pos="0.0378 -0.0125 -0.02" quat="1 1 0 0" />
                                        <geom class="finger_collision" type="box"
                                            name="left_finger_pad_8" size="0.015 0.0105 0.001"
                                            pos="0.0128 -0.0125 -0.02" quat="1 1 0 0" />
                                    </body>
                                    <body name="right_finger_link" pos="0.0687 0 0">
                                        <inertial pos="0.017344 0.0060692 0"
                                            quat="0.44937 -0.44937 0.545955 -0.545955"
                                            mass="0.034796"
                                            diaginertia="2.48002e-05 1.417e-05 1.20798e-05" />
                                        <joint name="right_finger" class="right_finger" />
                                        <geom pos="-0.0404 0.0575 0" quat="1 1 1 1" class="visual"
                                            mesh="vx300s_10_gripper_finger" />
                                        <geom class="finger_collision" type="box"
                                            name="right_finger_pad_0" size="0.01405 0.01405 0.001"
                                            pos="0.0478 0.0125 0.0106" quat="0.65 0.65 -0.27 0.27" />
                                        <geom class="finger_collision" type="box"
                                            name="right_finger_pad_1" size="0.01405 0.01405 0.001"
                                            pos="0.0478 0.0125 -0.0106" quat="0.65 0.65 -0.27 0.27" />
                                        <geom class="finger_collision" type="box"
                                            name="right_finger_pad_2" size="0.01058 0.01058 0.001"
                                            pos="0.0571 0.0125 0.0" quat="1 1 0 0" />
                                        <geom class="finger_collision" type="box"
                                            name="right_finger_pad_3" size="0.01 0.0105 0.001"
                                            pos="0.0378 0.0125 0.0" quat="1 1 0 0" />
                                        <geom class="finger_collision" type="box"
                                            name="right_finger_pad_4" size="0.015 0.0105 0.001"
                                            pos="0.0128 0.0125 0.0" quat="1 1 0 0" />
                                        <geom class="finger_collision" type="box"
                                            name="right_finger_pad_5" size="0.01 0.0105 0.001"
                                            pos="0.0378 0.0125 0.02" quat="1 1 0 0" />
                                        <geom class="finger_collision" type="box"
                                            name="right_finger_pad_6" size="0.015 0.0105 0.001"
                                            pos="0.0128 0.0125 0.02" quat="1 1 0 0" />
                                        <geom class="finger_collision" type="box"
                                            name="right_finger_pad_7" size="0.01 0.0105 0.001"
                                            pos="0.0378 0.0125 -0.02" quat="1 1 0 0" />
                                        <geom class="finger_collision" type="box"
                                            name="right_finger_pad_8" size="0.015 0.0105 0.001"
                                            pos="0.0128 0.0125 -0.02" quat="1 1 0 0" />
                                    </body>
                                </body>
                            </body>
                        </body>
                    </body>
                </body>
            </body>

        </body>
    </worldbody>

    <equality>
        <joint joint1="left_finger" joint2="right_finger" polycoef="0 -1 0 0 0" />
    </equality>

    <contact>
        <exclude body1="trunk" body2="shoulder_link" />
        <exclude body1="trunk" body2="FL_thigh" />
        <exclude body1="trunk" body2="FR_thigh" />
        <exclude body1="trunk" body2="RL_thigh" />
        <exclude body1="trunk" body2="RR_thigh" />
    </contact>

    <!-- <actuator>
    <motor class="abduction" name="FR_hip" joint="FR_hip_joint"/>
    <motor class="hip" name="FR_thigh" joint="FR_thigh_joint"/>
    <motor class="knee" name="FR_calf" joint="FR_calf_joint"/>
    <motor class="abduction" name="FL_hip" joint="FL_hip_joint"/>
    <motor class="hip" name="FL_thigh" joint="FL_thigh_joint"/>
    <motor class="knee" name="FL_calf" joint="FL_calf_joint"/>
    <motor class="abduction" name="RR_hip" joint="RR_hip_joint"/>
    <motor class="hip" name="RR_thigh" joint="RR_thigh_joint"/>
    <motor class="knee" name="RR_calf" joint="RR_calf_joint"/>
    <motor class="abduction" name="RL_hip" joint="RL_hip_joint"/>
    <motor class="hip" name="RL_thigh" joint="RL_thigh_joint"/>
    <motor class="knee" name="RL_calf" joint="RL_calf_joint"/>
  </actuator> -->

    <!-- <keyframe>
        <key name="home" qpos="0 0 0.27 1 0 0 0 0 0.9 -1.8 0 0.9 -1.8 0 0.9 -1.8 0 0.9 -1.8"
            ctrl="0 0.9 -1.8 0 0.9 -1.8 0 0.9 -1.8 0 0.9 -1.8" />
    </keyframe> -->
</mujoco>